2023-07-13 12:41:39,732 INFO    StreamThr :2327199 [internal.py:wandb_internal():86] W&B internal server running at pid: 2327199, started at: 2023-07-13 12:41:39.732305
2023-07-13 12:41:39,733 DEBUG   HandlerThread:2327199 [handler.py:handle_request():144] handle_request: status
2023-07-13 12:41:39,733 INFO    WriterThread:2327199 [datastore.py:open_for_write():85] open: /home/yohann/Code/place_recognition/ACGiS-Net/wandb/run-20230713_124139-f4w86uyb/run-f4w86uyb.wandb
2023-07-13 12:41:39,734 DEBUG   SenderThread:2327199 [sender.py:send():369] send: header
2023-07-13 12:41:39,764 DEBUG   SenderThread:2327199 [sender.py:send():369] send: run
2023-07-13 12:41:44,766 DEBUG   HandlerThread:2327199 [handler.py:handle_request():144] handle_request: keepalive
2023-07-13 12:41:49,767 DEBUG   HandlerThread:2327199 [handler.py:handle_request():144] handle_request: keepalive
2023-07-13 12:41:54,768 DEBUG   HandlerThread:2327199 [handler.py:handle_request():144] handle_request: keepalive
2023-07-13 12:41:59,770 DEBUG   HandlerThread:2327199 [handler.py:handle_request():144] handle_request: keepalive
2023-07-13 12:42:04,771 DEBUG   HandlerThread:2327199 [handler.py:handle_request():144] handle_request: keepalive
2023-07-13 12:42:09,773 DEBUG   HandlerThread:2327199 [handler.py:handle_request():144] handle_request: keepalive
2023-07-13 12:42:14,774 DEBUG   HandlerThread:2327199 [handler.py:handle_request():144] handle_request: keepalive
2023-07-13 12:42:15,632 INFO    SenderThread:2327199 [retry.py:__call__():172] Retry attempt failed:
Traceback (most recent call last):
  File "/home/yohann/Environments/anaconda3/envs/tcnn/lib/python3.9/site-packages/urllib3/connectionpool.py", line 466, in _make_request
    six.raise_from(e, None)
  File "<string>", line 3, in raise_from
  File "/home/yohann/Environments/anaconda3/envs/tcnn/lib/python3.9/site-packages/urllib3/connectionpool.py", line 461, in _make_request
    httplib_response = conn.getresponse()
  File "/home/yohann/Environments/anaconda3/envs/tcnn/lib/python3.9/http/client.py", line 1377, in getresponse
    response.begin()
  File "/home/yohann/Environments/anaconda3/envs/tcnn/lib/python3.9/http/client.py", line 320, in begin
    version, status, reason = self._read_status()
  File "/home/yohann/Environments/anaconda3/envs/tcnn/lib/python3.9/http/client.py", line 281, in _read_status
    line = str(self.fp.readline(_MAXLINE + 1), "iso-8859-1")
  File "/home/yohann/Environments/anaconda3/envs/tcnn/lib/python3.9/socket.py", line 704, in readinto
    return self._sock.recv_into(b)
  File "/home/yohann/Environments/anaconda3/envs/tcnn/lib/python3.9/ssl.py", line 1242, in recv_into
    return self.read(nbytes, buffer)
  File "/home/yohann/Environments/anaconda3/envs/tcnn/lib/python3.9/ssl.py", line 1100, in read
    return self._sslobj.read(len, buffer)
socket.timeout: The read operation timed out

During handling of the above exception, another exception occurred:

Traceback (most recent call last):
  File "/home/yohann/Environments/anaconda3/envs/tcnn/lib/python3.9/site-packages/requests/adapters.py", line 487, in send
    resp = conn.urlopen(
  File "/home/yohann/Environments/anaconda3/envs/tcnn/lib/python3.9/site-packages/urllib3/connectionpool.py", line 798, in urlopen
    retries = retries.increment(
  File "/home/yohann/Environments/anaconda3/envs/tcnn/lib/python3.9/site-packages/urllib3/util/retry.py", line 550, in increment
    raise six.reraise(type(error), error, _stacktrace)
  File "/home/yohann/Environments/anaconda3/envs/tcnn/lib/python3.9/site-packages/urllib3/packages/six.py", line 770, in reraise
    raise value
  File "/home/yohann/Environments/anaconda3/envs/tcnn/lib/python3.9/site-packages/urllib3/connectionpool.py", line 714, in urlopen
    httplib_response = self._make_request(
  File "/home/yohann/Environments/anaconda3/envs/tcnn/lib/python3.9/site-packages/urllib3/connectionpool.py", line 468, in _make_request
    self._raise_timeout(err=e, url=url, timeout_value=read_timeout)
  File "/home/yohann/Environments/anaconda3/envs/tcnn/lib/python3.9/site-packages/urllib3/connectionpool.py", line 357, in _raise_timeout
    raise ReadTimeoutError(
urllib3.exceptions.ReadTimeoutError: HTTPSConnectionPool(host='api.wandb.ai', port=443): Read timed out. (read timeout=10)

During handling of the above exception, another exception occurred:

Traceback (most recent call last):
  File "/home/yohann/Environments/anaconda3/envs/tcnn/lib/python3.9/site-packages/wandb/sdk/lib/retry.py", line 131, in __call__
    result = self._call_fn(*args, **kwargs)
  File "/home/yohann/Environments/anaconda3/envs/tcnn/lib/python3.9/site-packages/wandb/sdk/internal/internal_api.py", line 321, in execute
    return self.client.execute(*args, **kwargs)  # type: ignore
  File "/home/yohann/Environments/anaconda3/envs/tcnn/lib/python3.9/site-packages/wandb/vendor/gql-0.2.0/wandb_gql/client.py", line 52, in execute
    result = self._get_result(document, *args, **kwargs)
  File "/home/yohann/Environments/anaconda3/envs/tcnn/lib/python3.9/site-packages/wandb/vendor/gql-0.2.0/wandb_gql/client.py", line 60, in _get_result
    return self.transport.execute(document, *args, **kwargs)
  File "/home/yohann/Environments/anaconda3/envs/tcnn/lib/python3.9/site-packages/wandb/sdk/lib/gql_request.py", line 55, in execute
    request = self.session.post(self.url, **post_args)
  File "/home/yohann/Environments/anaconda3/envs/tcnn/lib/python3.9/site-packages/requests/sessions.py", line 635, in post
    return self.request("POST", url, data=data, json=json, **kwargs)
  File "/home/yohann/Environments/anaconda3/envs/tcnn/lib/python3.9/site-packages/requests/sessions.py", line 587, in request
    resp = self.send(prep, **send_kwargs)
  File "/home/yohann/Environments/anaconda3/envs/tcnn/lib/python3.9/site-packages/requests/sessions.py", line 701, in send
    r = adapter.send(request, **kwargs)
  File "/home/yohann/Environments/anaconda3/envs/tcnn/lib/python3.9/site-packages/requests/adapters.py", line 533, in send
    raise ReadTimeout(e, request=request)
requests.exceptions.ReadTimeout: HTTPSConnectionPool(host='api.wandb.ai', port=443): Read timed out. (read timeout=10)
2023-07-13 12:42:19,776 DEBUG   HandlerThread:2327199 [handler.py:handle_request():144] handle_request: keepalive
2023-07-13 12:42:24,779 DEBUG   HandlerThread:2327199 [handler.py:handle_request():144] handle_request: keepalive
2023-07-13 12:42:29,780 DEBUG   HandlerThread:2327199 [handler.py:handle_request():144] handle_request: keepalive
2023-07-13 12:42:34,781 DEBUG   HandlerThread:2327199 [handler.py:handle_request():144] handle_request: keepalive
2023-07-13 12:42:39,783 DEBUG   HandlerThread:2327199 [handler.py:handle_request():144] handle_request: cancel
2023-07-13 12:42:39,783 DEBUG   HandlerThread:2327199 [handler.py:handle_request():144] handle_request: cancel
2023-07-13 12:42:40,300 DEBUG   HandlerThread:2327199 [handler.py:handle_request():144] handle_request: shutdown
2023-07-13 12:42:40,300 INFO    HandlerThread:2327199 [handler.py:finish():854] shutting down handler
2023-07-13 12:42:40,783 INFO    WriterThread:2327199 [datastore.py:close():298] close: /home/yohann/Code/place_recognition/ACGiS-Net/wandb/run-20230713_124139-f4w86uyb/run-f4w86uyb.wandb
2023-07-13 12:42:49,925 DEBUG   SenderThread:2327199 [sender.py:send():378] Record cancelled: run
2023-07-13 12:42:49,925 INFO    SenderThread:2327199 [sender.py:finish():1526] shutting down sender
